File: fsilica_100mN_01_data.txt
Specimen: 1	Specimen: 1	Specimen: 2	Specimen: 2	Specimen: 3	Specimen: 3	Specimen: 4	Specimen: 4	Specimen: 5	Specimen: 5	Specimen: 6	Specimen: 6	Specimen: 7	Specimen: 7	Specimen: 8	Specimen: 8	Specimen: 9	Specimen: 9
Displacement Into Surface	Load On Sample	Displacement Into Surface	Load On Sample	Displacement Into Surface	Load On Sample	Displacement Into Surface	Load On Sample	Displacement Into Surface	Load On Sample	Displacement Into Surface	Load On Sample	Displacement Into Surface	Load On Sample	Displacement Into Surface	Load On Sample	Displacement Into Surface	Load On Sample
nm	mN	nm	mN	nm	mN	nm	mN	nm	mN	nm	mN	nm	mN	nm	mN	nm	mN
126.1411314	2.696162685	99.22957627	1.933642821	96.20389154	1.924099616	98.40731737	1.904296618	98.40535046	1.914102601	98.19848193	1.904314111	95.17693999	1.914383388	96.80382724	1.933853035	4.304097658	7.75945E-05
174.9932512	4.653261184	156.9557541	3.889972531	156.01108	3.875345926	156.0953796	3.860629649	158.0669229	3.87026479	158.5201218	3.870225726	154.2940013	3.870592691	156.6209215	3.890001608	101.0376198	1.923680682
215.2695535	6.611102448	201.9028425	5.847409102	199.0476746	5.837851445	199.3916635	5.818209233	199.6424604	5.8279935	201.5895506	5.822921671	197.7815341	5.818349095	199.3767781	5.847627972	161.3350967	3.874884363
250.5976701	8.569372281	235.4361232	7.805834321	235.2310102	7.796047219	234.6884207	7.776481704	237.2965564	7.786061839	236.5218491	7.786129072	233.8321221	7.781459625	237.0593851	7.805693746	203.0302499	5.837505966
278.9375648	10.52824741	269.0537838	9.764252195	265.7580306	9.754732913	266.249663	9.735077727	267.4720925	9.7545846	268.3972647	9.739794583	264.4690972	9.735232413	268.4194951	9.764307168	239.9838029	7.795634924
306.8724057	12.48715761	295.3640972	11.72330304	293.3994694	11.71366853	294.8988228	11.69392598	294.7726505	11.71354972	295.3943201	11.69388265	292.3552015	11.69905011	293.9470905	11.72342581	270.814625	9.754294219
331.8395776	14.44632485	321.2962777	13.68238662	320.9188087	13.67261471	320.6811393	13.65302255	321.3307285	13.67257914	321.602194	13.66274903	318.2665838	13.65813553	321.2625149	13.68238955	299.2440434	11.71316151
355.4313483	16.40561121	345.4531915	15.64162397	343.9905537	15.63194613	344.3081235	15.61230581	345.6316024	15.63180406	345.2274292	15.62203246	342.244876	15.61248505	346.8141887	15.64150606	324.9780527	13.67226226
376.0612671	18.36515413	367.6247236	17.60103328	366.9458989	17.58638429	367.4523089	17.57163088	368.3722469	17.58135748	367.3424618	17.5618334	365.574785	17.57179405	368.8729946	17.60092513	349.2671263	15.63148817
398.3844177	20.32455036	389.2410223	19.56049068	388.3485601	19.55076359	388.2583281	19.53115848	388.6945635	19.54092702	388.4631735	19.53114041	386.3888489	19.54112762	388.7901667	19.56052972	371.3962495	17.59090117
418.4371429	22.28414325	412.5534096	21.51980114	408.0283102	21.5103888	409.5492503	21.50045071	409.6264015	21.50044374	409.1204748	21.50048755	406.9309943	21.49087143	410.2025779	21.52000476	393.5324333	19.55031354
437.4276001	24.24382815	429.9465893	23.47962436	424.9449674	23.47025335	427.8820335	23.45038589	429.1079779	23.46008609	428.3830915	23.4503422	425.9567399	23.45055325	426.8657088	23.47989122	413.8153051	21.50988645
456.6216591	26.2034954	448.8350643	25.43931803	446.0212888	25.42975755	446.9122053	25.41987394	447.4606122	25.41982622	446.6338503	25.41009114	444.7790812	25.41025267	446.5430784	25.43951654	433.0345053	23.46955149
474.0416496	28.16331632	465.6464506	27.39919163	465.5802907	27.38939319	465.0017084	27.36983018	465.3885951	27.37960312	464.1171422	27.36990655	462.335522	27.37006175	466.4921687	27.39911831	452.3320611	25.4243064
490.7085174	30.12320248	483.8754858	29.34913575	481.624264	29.34933331	482.5607898	29.33944565	483.1156929	29.33939742	481.6061014	29.32972147	481.4933433	29.32973209	482.2163043	29.35908608	470.6621554	27.38404844
508.3736504	32.08300215	500.2436931	31.31885438	496.667703	31.3093601	499.1421107	31.29933917	499.2599013	31.29932884	498.4610018	31.28959131	497.2631594	31.28969592	499.1488146	31.31894917	488.1158807	29.34876972
524.4830404	34.03803326	516.9663071	33.27873565	514.4270642	33.2691516	515.285894	33.25927058	515.6529103	33.25923869	515.481505	33.24944679	512.8787261	33.24967311	515.3870405	33.27887239	504.0816794	31.30871656
538.8967674	36.00301791	531.7804198	35.23878224	528.3985619	35.22927124	531.7765453	35.20936529	530.8302451	35.21925385	529.7286202	35.20954252	528.1641572	35.19987224	529.7483846	35.23895821	521.1694255	33.2685662
554.3294725	37.96301094	547.5744245	37.19384061	546.1093835	37.18906693	547.1485369	37.16936355	548.1317924	37.17908498	545.0722478	37.16954325	543.05976	37.16971844	544.873459	37.19897785	537.8759324	35.22844886
569.7810368	39.91809902	561.2492777	39.15888922	560.8277173	39.14912185	561.6175648	39.12944003	561.744865	39.13923564	560.2831442	39.12955548	558.9240156	39.12967406	559.1242619	39.15907321	550.8940179	37.18865105
584.2501937	41.88307884	577.0647808	41.11884903	574.7176652	41.10924853	575.8247805	41.0895392	576.5921406	41.09927937	574.498556	41.08965394	573.4729415	41.08974362	572.8414518	41.11921188	566.5067439	39.14862845
598.5972912	43.84316591	590.4611839	43.07901695	588.7538711	43.06936254	590.3713478	43.0594156	590.4984438	43.05940461	589.3407249	43.0496981	587.8238825	43.04983033	586.4395499	43.07936079	581.8135468	41.10863234
612.0513687	45.798427	604.781177	45.03419975	602.3762246	45.02951239	603.1742755	45.0196364	604.15423	45.00974491	601.9223393	45.00993809	600.5016518	45.01006199	601.994717	45.03933955	594.0071314	43.06890595
625.3478081	47.7635084	617.9006642	46.99439	615.3114888	46.98972176	617.1690769	46.97975085	617.0372367	46.97976544	614.8273572	46.97015005	613.9209198	46.97022941	613.6019105	46.99966108	608.2549627	45.02900157
638.466707	49.72860518	631.455975	48.96434895	628.8405264	48.94987968	629.713033	48.93999115	631.0811035	48.93987875	628.0192005	48.93033717	627.1266164	48.94022197	627.583554	48.9597763	621.7755575	46.98915857
651.6825598	51.6838869	644.5382643	50.9147355	642.583953	50.91001902	643.3945252	50.87071247	643.711408	50.90011452	640.5103393	50.89058498	640.2652134	50.89060704	641.4095311	50.91990483	634.2666449	48.94940344
663.9130779	53.6441573	657.0079668	52.87988517	653.6795784	52.87038775	655.9791109	52.8603689	656.3689271	52.86034792	653.6705488	52.85077482	652.790791	52.85085132	652.3611464	52.88028293	647.8552868	50.90955278
677.08206	55.60924972	669.838276	54.84010002	666.2946526	54.82081819	668.5236711	54.82060876	669.295341	54.82055802	666.2964377	54.8110094	665.3321089	54.81109162	664.6659828	54.84054344	660.0425883	52.86982378
688.781806	57.5695661	681.2019473	56.80044231	679.0025665	56.79085388	681.260748	56.78083173	680.6590441	56.7809035	678.3406788	56.7712929	676.8206237	56.77142333	676.6903813	56.80082815	671.3251812	54.83017333
701.1960782	59.52491725	693.698345	58.76068596	690.5778734	58.75118104	692.319315	58.74120047	693.5853845	58.7411136	690.0385021	58.73160632	688.8304689	58.73170964	689.2669431	58.7610648	684.2268634	56.78057533
713.4841855	61.48518264	705.5019298	60.72098969	702.1596031	60.71150764	704.7130788	60.69654973	706.0821149	60.70136091	701.484574	60.69194162	700.8625112	60.69199396	700.3173996	60.721434	695.5529612	58.75072751
724.754796	63.45534283	717.4905085	62.68127728	714.2103179	62.67179359	715.5622715	62.66183981	717.140933	62.66173096	712.1223905	62.65234695	712.3444751	62.65232587	712.0519745	62.68174357	706.9792461	60.71106418
736.2843547	65.41077061	728.4402532	64.64165508	726.4494269	64.62225658	727.5950665	64.6074136	728.8688169	64.62204166	723.6365317	64.61267604	723.4004293	64.61269476	723.6588672	64.64206421	717.9286065	62.67144227
747.2582714	67.37605318	739.1079512	66.61186395	738.0764209	66.59238589	739.1385699	66.58244979	740.253875	66.58238202	735.2582133	66.5729957	734.4864739	66.57306085	734.3485166	66.60246442	730.1831188	64.63170681
758.6633435	69.33149173	750.6580729	68.56238272	749.0656592	68.5527638	750.2516662	68.53300662	751.662568	68.54272033	746.2107702	68.53337345	745.2576685	68.53345436	745.5752692	68.56281788	742.1378358	66.59199722
769.1732075	71.29681277	761.5411275	70.52766936	759.9415601	70.51315153	761.4356439	70.49826722	763.14151	70.50305239	757.5928655	70.49371374	755.8803895	70.49386066	757.1447793	70.52314144	753.1071855	68.55237326
780.7381442	73.25223412	772.1256383	72.48317524	770.8504216	72.47353476	771.8183765	72.45379075	773.8100574	72.46345475	768.6149271	72.45408523	767.2652091	72.44439388	767.8601605	72.48353917	763.7529012	70.50297069
791.1439674	75.21756277	782.3075354	74.44361936	781.5679605	74.44373976	783.0122466	74.41414694	784.5667854	74.42384942	778.2457161	74.41457759	777.0827231	74.41467669	778.4908936	74.44394419	774.7410223	72.47315158
801.4154774	77.17309636	792.9767081	76.404021	791.4711565	76.39440203	792.6244653	76.37464067	795.6017334	76.38421979	788.5742549	76.37500928	788.7165092	76.37499479	789.4866155	76.40431734	785.4485382	74.43355015
811.5900573	79.12373492	803.2693533	78.36445537	802.225035	78.35479712	803.0670927	78.33506204	805.9166536	78.34465273	798.879103	78.33544292	798.5725156	78.33546734	799.9652645	78.36473549	795.1506233	76.39403602
821.9145909	81.09887704	813.2913432	80.32981648	812.4245409	80.31524015	813.6655778	80.29056647	816.5162487	80.30506069	809.2312567	80.29587236	808.4003491	80.28613567	809.6157962	80.33503213	805.8200804	78.3544377
832.0792632	83.05932298	823.2216009	82.28047554	822.532229	82.27569121	823.5051455	82.25594349	826.3922359	82.2655316	819.832946	82.25627997	819.0116177	82.25634908	820.4441666	82.28561298	816.0181825	80.30507365
842.6993783	85.00501925	833.241124	84.25074004	832.424218	84.24596744	832.884567	84.2164572	836.2481203	84.22600411	830.3765215	84.21669257	828.8316965	84.21682457	830.048574	84.24610688	825.8573485	82.27535403
852.0980151	86.98024165	842.6239822	86.21125324	842.8753632	86.20638835	843.0309258	86.17690403	846.1871681	86.18646935	840.2746572	86.17716126	838.0981383	86.1773482	840.2940596	86.20654493	835.3391867	84.23585876
862.0087495	88.94070947	852.1463021	88.17175424	852.9449703	88.16684243	852.5877905	88.13740209	856.3764679	88.14691284	849.5754049	88.13768181	847.1601815	88.13788944	849.7714924	88.16704975	845.1487242	86.19633498
872.0512309	90.89135909	861.9824373	90.13713118	862.8589367	90.12731003	861.9047586	90.09792097	866.7421548	90.10734076	858.9822662	90.0981931	857.7941173	90.09829385	859.7121576	90.12751421	854.3042334	88.15686798
881.1870596	92.85189414	871.5348326	92.09762938	872.187524	92.07802167	870.7380131	92.05848192	875.852858	92.06787789	869.0639177	92.05864559	866.3225863	92.05888156	869.0011283	92.09784198	863.6605134	90.11738353
891.0564905	94.81236533	881.0950036	94.05322355	881.4058351	94.03854955	879.8218797	94.01902096	884.5978113	94.02844682	879.0464007	94.00929995	875.3566004	94.01942506	878.2524251	94.0485596	873.1157335	92.07789032
900.4447063	96.77287827	890.0267708	96.018679	890.5153051	96.00889353	889.2320122	95.97953157	893.9314986	95.98896436	887.7212001	95.97968136	885.1155917	95.97990541	887.5892189	96.00907642	882.8204857	94.0383753
907.6666926	98.34131372	899.2817615	97.97429959	900.2190663	97.96937904	898.9038684	97.94001925	903.8044352	97.94943489	898.0186347	97.94011483	893.8462283	97.94047533	896.6628141	97.96961605	892.0146365	95.99890475
910.5359835	98.38029065	901.2370265	98.36149196	902.0301606	98.36148744	899.5194739	98.33223167	905.7642472	98.34153031	899.5551975	98.33224707	896.0283545	98.33255127	898.8127056	98.3616948	901.3127474	97.95942504
911.8496825	98.38017627	904.0506992	98.4004735	904.849337	98.38085536	902.0952531	98.36142728	907.6347048	98.3707874	902.0671663	98.36144835	898.0356417	98.3519898	901.2576859	98.39090179	902.999832	98.35154412
912.648359	98.38010679	905.144725	98.40037823	906.7931574	98.38068622	903.9215281	98.3612683	910.2194933	98.37056233	903.975343	98.3612822	900.2886041	98.35179368	902.2545675	98.39081494	905.7590743	98.38072379
913.2003446	98.38005877	905.4491801	98.40035167	907.7554264	98.38060243	904.4131678	98.36122549	911.2255181	98.37047486	903.9536782	98.3612841	900.4041302	98.35178357	902.9382488	98.39075539	906.7461691	98.38063789
913.5608579	98.38002736	906.0426372	98.40029994	907.9747597	98.38058339	904.3411605	98.36123178	910.5255302	98.37053577	904.6548659	98.36122301	900.2378336	98.35179801	902.9887271	98.39075097	908.2789782	98.38050438
913.8869492	98.379999	906.4603983	98.4002636	908.2528968	98.38055918	904.3795878	98.36122848	911.354428	98.37046362	905.6909465	98.36113289	900.5053863	98.3517748	903.2306723	98.39072987	908.3431606	98.38049881
913.7304158	98.38001263	906.8064466	98.40023349	908.5475277	98.38053355	905.0060438	98.36117395	911.9430927	98.37041242	905.5817936	98.36114235	900.5764519	98.35176858	903.0814371	98.39074292	909.1423734	98.38042914
913.4720507	98.38003511	907.2901832	98.40019136	909.7457284	98.3804293	903.9860194	98.36126277	912.3804464	98.37037435	905.7974941	98.36112365	901.6679593	98.35167344	903.9698515	98.3906655	909.6246266	98.3803872
913.7895365	98.3800075	907.4662725	98.40017602	909.7642684	98.38042768	904.8286836	98.36118942	913.1906989	98.37030381	906.7346125	98.36104203	901.1409584	98.35171943	904.0192542	98.39066122	909.2628502	98.38041878
914.0496523	98.37998487	907.3124837	98.4001894	910.5128353	98.38036251	905.3741064	98.36114196	913.3455101	98.37029035	907.6459145	98.36096267	901.435044	98.35169375	903.6832134	98.39069052	909.804623	98.38037166
914.1900084	98.3799727	907.2978173	98.40019069	910.4567949	98.38036741	904.9876471	98.36117561	913.2091734	98.37030225	906.8304033	98.3610337	901.7857808	98.35166319	904.3084506	98.39063605	910.6927562	98.38029428
914.1768999	98.37997381	906.7775768	98.40023602	911.412609	98.38028426	905.4531124	98.36113509	913.6156912	98.37026681	906.9535958	98.36102299	901.8174055	98.35166044	903.8899429	98.39067243	910.4342426	98.38031674
913.2085816	98.38005807	907.3373288	98.40018725	911.3569272	98.38028907	905.7371492	98.36111038	914.1290587	98.37022218	906.4091541	98.36107034	901.4933457	98.3516886	904.5284465	98.39061684	910.6181812	98.38030083
913.8537933	98.38000185	907.4990756	98.40017319	912.0344992	98.38023009	905.1294621	98.36116337	913.6011784	98.37026803	906.7345731	98.36104205	902.0039971	98.35164418	904.3128792	98.39063566	910.8695274	98.38027889
913.4742341	98.38003493	907.9075138	98.4001376	911.9071055	98.3802412	905.6300656	98.36111976	914.0270582	98.37023102	907.8839574	98.36094196	901.7975426	98.35166214	904.6021532	98.39061044	911.4858787	98.3802253
913.301924	98.38004998	907.7852786	98.40014819	912.3802986	98.38020002	905.6129171	98.36112132	914.4679974	98.37019268	907.9648401	98.36093498	902.2709046	98.35162088	904.8577232	98.39058821	911.9028755	98.38018896
913.7893683	98.38000754	908.3335564	98.40010046	912.2206346	98.38021389	905.9675891	98.36109047	915.0516419	98.37014191	907.9030169	98.36094029	902.3469898	98.3516143	904.6765769	98.39060399	912.4503848	98.38014131
914.463982	98.3799488	907.9416816	98.40013463	912.7501215	98.38016783	905.8346276	98.36110201	915.0020759	98.37014613	907.4259841	98.36098184	903.2147598	98.35153871	904.5606872	98.39061397	912.3008709	98.38015432
913.7416375	98.38001176	908.1335477	98.40011784	912.8676238	98.38015761	906.4424387	98.36104915	915.3146518	98.370119	904.387415	98.36124644	902.1226797	98.35163369	904.428304	98.39062555	912.7616108	98.38011422
913.1397697	98.38006408	908.4028634	98.40009441	912.5584406	98.38018449	906.7834856	98.36101944	914.8613513	98.37015853	903.0613167	98.36136193	902.5064034	98.35160037	904.9018736	98.39058434	912.9226021	98.38010027
912.8136363	98.38009246	908.4864434	98.4000871	912.1061923	98.38022385	906.9266107	98.36100698	915.669452	98.37008817	903.16443	98.36135291	903.507555	98.35151316	904.6690959	98.39060463	913.6257225	98.38003903
913.6851008	98.38001666	909.011056	98.40004144	913.1007305	98.38013735	907.1184991	98.36099026	915.7253016	98.37008327	904.0212321	98.36127838	902.523758	98.35159881	905.7005721	98.39051483	913.8032071	98.38002359
913.5256989	98.38003052	908.2491441	98.40010776	913.6653561	98.38008819	907.4875132	98.36095815	915.9790742	98.37006109	904.5646544	98.36123107	902.1573889	98.35163073	905.5897021	98.39052444	913.6407853	98.38003774
913.8976862	98.37999813	907.9045996	98.40013783	914.2357185	98.38003856	908.3154762	98.36088621	916.6588116	98.37000197	903.7405372	98.36130283	902.4995204	98.35160089	906.3780801	98.3904558	913.6547707	98.38003652
913.759798	98.38001013	908.0362271	98.40012632	913.3800913	98.38011304	907.9523232	98.36091779	916.5533108	98.37001118	905.6378738	98.3611377	902.665961	98.35158645	905.8627636	98.3905007	913.9835638	98.38000795
913.8772061	98.37999991	908.0703254	98.40012338	914.243038	98.38003795	907.8602369	98.3609258	916.7461288	98.36999438	905.4068113	98.36115774	902.7370265	98.35158021	905.8558736	98.39050128	914.2854656	98.37998165
913.1602399	98.38006235	908.0456193	98.40012552	913.8549719	98.38007167	908.1725994	98.36089865	917.7367344	98.36990815	905.5178129	98.36114815	903.1558882	98.35154373	906.1071409	98.39047936	914.3743881	98.37997395
913.9069247	98.37999736	908.2331826	98.40010924	914.3156153	98.38003159	909.5656432	98.36077733	918.2762761	98.36986121	906.2792382	98.36108185	903.3517301	98.35152671	906.419362	98.39045222	914.0807367	98.37999953
913.5578434	98.38002773	907.6620262	98.40015894	914.1093386	98.38004955	908.7614691	98.36084744	917.6601914	98.36991488	906.1657826	98.36109169	902.8240123	98.35157261	906.3343078	98.39045961	914.4704834	98.3799656
913.0058157	98.38007578	908.891574	98.40005187	914.5689063	98.38000957	909.5385173	98.36077976	917.9437241	98.36989018	906.7715938	98.36103899	902.7244067	98.35158128	906.4070163	98.39045325	914.4342716	98.37996875
912.620161	98.38010936	907.822732	98.40014486	914.6717076	98.3800006	909.4371087	98.36078861	918.3050634	98.36985871	906.7958244	98.36103686	902.0547019	98.35163953	906.730711	98.39042512	914.6425916	98.37995063
913.8616618	98.38000129	909.1153869	98.40003234	915.0670931	98.37996621	910.014801	98.36073833	917.9858633	98.36988649	907.6382835	98.36096354	902.441294	98.3516059	906.6241436	98.39043441	914.7056984	98.37994516
913.4763656	98.38003486	909.1817558	98.40002656	914.7231299	98.37999613	909.8660632	98.36075126	918.554448	98.36983702	907.1117697	98.36100934	902.8135438	98.3515735	906.294557	98.390463	915.2854771	98.37989468
913.0290382	98.38007377	909.005019	98.40004196	915.8091001	98.37990164	909.7668059	98.36075997	918.3381534	98.36985583	908.136376	98.36092017	903.052412	98.35155269	906.3715682	98.39045631	915.3181071	98.37989187
912.9671652	98.38007916	909.3037368	98.40001598	915.5099567	98.37992768	910.2677676	98.36071639	918.5854719	98.36983433	908.5722306	98.36088226	902.6874773	98.35158442	906.9426636	98.39040656	915.8914319	98.37984194
912.5227061	98.38011782	908.5339366	98.40008296	915.7364609	98.37990798	910.2316158	98.36071959	919.018881	98.36979658	908.2637199	98.3609091	903.1952601	98.3515402	906.6367415	98.39043326	915.6945893	98.37985912
912.646927	98.38010705	908.2876384	98.4001044	916.1164283	98.37987492	911.5084878	98.36060837	919.2966767	98.36977241	908.4636437	98.36089174	902.8231543	98.35157257	906.5559898	98.39044028	915.6669828	98.37986153
912.5617474	98.38011445	908.1489093	98.4001165	915.6537821	98.37991517	910.3242469	98.36071143	919.831557	98.36972586	907.9507551	98.36093637	903.1172396	98.35154699	906.8187307	98.39041744	915.3941274	98.37988533
913.1703859	98.38006148	908.3027676	98.4001031	915.4019685	98.37993707	911.6950599	98.36059214	920.2753641	98.36968726	908.6809855	98.36087277	902.5421929	98.35159699	906.7006897	98.39042769	916.2582369	98.37981008
912.8682761	98.38008775	908.7449107	98.40006457	915.1429838	98.37995964	911.2989202	98.36062668	919.943256	98.36971614	908.2251076	98.36091252	902.5092781	98.35159989	906.2054522	98.39047086	916.4776719	98.37979099
912.8304268	98.38009108	907.7377416	98.40015225	916.1690745	98.37987029	911.2900184	98.36062743	920.2447164	98.36968987	909.3400702	98.36081543	902.0274551	98.3516418	907.2978819	98.39037564	916.6361532	98.37977722
912.9758027	98.38007844	908.2573344	98.40010706	915.8624015	98.37989707	912.211205	98.36054724	920.1990945	98.36969389	909.3245009	98.36081681	902.7797709	98.35157633	907.3964061	98.39036713	917.0380906	98.37974222
912.694131	98.38010297	908.5517495	98.40008143	915.9164388	98.37989232	912.8161471	98.36049461	920.4679263	98.36967048	909.5269346	98.3607992	902.2868328	98.3516192	906.4228606	98.39045193	916.9767802	98.37974756
912.5935333	98.38011172	908.280352	98.40010495	916.0737411	98.37987865	912.2141976	98.36054699	920.7984296	98.36964176	909.480888	98.3608032	902.3446319	98.35161417	907.1015216	98.39039274	917.18761	98.37972925
913.1666741	98.38006182	908.0283168	98.40012696	915.6103777	98.37991896	912.7660738	98.36049907	920.8184235	98.36963995	909.7539575	98.36077946	902.2955821	98.35161843	907.2954206	98.39037589	917.2858548	98.3797207
912.9133288	98.38008391	908.7687845	98.4000625	915.5736996	98.37992216	912.9823438	98.3604802	921.2149011	98.36960546	909.8384258	98.3607721	901.7130057	98.35166917	907.2347478	98.39038111	917.5554869	98.37969722
912.5380723	98.3801166	908.2442414	98.40010814	914.9830477	98.37997355	913.1247517	98.36046782	921.6042076	98.36957157	909.8318205	98.36077268	901.8464594	98.35165753	908.0145202	98.39031327	917.6738105	98.37968695
913.2245188	98.38005688	908.3106103	98.40010235	915.4569577	98.37993227	913.2528175	98.36045667	921.8472233	98.36955046	909.6903975	98.36078498	901.7794821	98.35166334	908.1897745	98.39029789	917.5590761	98.37969695
911.8660844	98.38017504	908.9442261	98.40004711	915.6877645	98.37991224	912.69748	98.36050507	921.4763913	98.3695827	909.9297626	98.36076417	902.3410479	98.35161445	907.7361291	98.39033749	916.8401836	98.37975957
912.4596633	98.38012339	907.9169775	98.40013666	914.8127754	98.37998836	913.4673568	98.36043803	922.2708658	98.36951359	910.0508038	98.36075361	901.7480735	98.35166606	908.2276259	98.39029469	917.0187438	98.37974402
911.8147046	98.38017953	908.5333823	98.40008292	914.492477	98.38001629	913.5739093	98.36042879	922.3238468	98.36950896	909.7430102	98.36078041	901.8166291	98.35166011	908.0206641	98.39031271	917.7907056	98.37967682
911.9366791	98.38016891	908.7094715	98.40006769	913.5590424	98.3800975	913.7923306	98.36040979	923.026531	98.36944785	909.8310641	98.36077279	901.6983787	98.35167037	908.8269692	98.39024244	917.2435589	98.37972448
903.0069146	95.2820448	908.9120667	98.40004999	913.8590637	98.38007139	913.8427556	98.3604054	923.0048571	98.36944971	910.0903425	98.36075024	901.6767365	98.35167227	908.826882	98.39024244	917.1704164	98.37973089
895.5678131	93.32136226	909.1408438	98.40003012	913.7384024	98.38008187	914.2024814	98.36037412	922.8776075	98.36946074	909.9914636	98.36075884	901.4125835	98.3516952	908.3885575	98.39028057	917.5823917	98.379695
887.8142371	91.36070709	903.3487089	96.4882379	909.4151912	96.45835479	909.3199084	96.42888936	918.569743	96.44773254	905.7265787	96.4194135	896.8613425	96.43979474	903.5360794	96.45879333	917.8868021	98.3796685
880.3690122	89.40002492	896.2217843	94.52752867	901.6679023	94.49769915	901.9872197	94.45839143	911.686314	94.4870018	897.6375766	94.4587879	889.6805293	94.47909012	897.0661525	94.498027	912.4433398	96.44823262
872.9115826	87.43934386	889.2924163	92.56680219	893.8051421	92.53705341	895.0577154	92.49766493	904.4407303	92.5263026	889.8282346	92.49813783	882.2164454	92.51840993	889.2917988	92.53737422	904.901796	94.48755945
864.928572	85.48361177	882.5698378	90.60115439	885.9287415	90.57640885	887.6766005	90.54678446	897.2962471	90.56559455	882.7446026	90.53742461	874.2855092	90.55777042	882.3973215	90.57664473	897.5818236	92.52686701
856.8489095	83.51808141	874.358038	88.65034615	877.4883075	88.61581332	880.8049757	88.57624619	889.7924756	88.60491784	875.641596	88.57671302	867.2366051	88.59705408	874.050687	88.61604169	889.8007385	90.56621463
849.3236676	81.55740608	867.2304365	86.69454016	869.742034	86.65515728	873.2201741	86.62538338	883.1169619	86.64416884	867.5001843	86.61609163	859.4944226	86.64620463	866.9596957	86.65532925	882.2175602	88.60554494
842.0396374	79.59180641	859.7157466	84.72896119	862.1205259	84.69449053	865.8969236	84.66469103	874.5396362	84.68358542	859.5358859	84.65545484	851.6349724	84.6757521	859.3918129	84.69465829	874.270435	86.644907
834.3527445	77.63604836	852.8582978	82.76332495	854.730636	82.73380342	858.7945316	82.70397944	867.5406759	82.72286456	851.9616878	82.69478418	843.780709	82.71510571	851.6661513	82.73400099	867.1440267	84.68419749
826.4645888	75.67540446	844.5597509	80.7978141	847.6770664	80.77308699	850.8134759	80.73353757	860.1386809	80.76217873	844.8414163	80.73407393	836.7382066	80.75438861	843.9627058	80.77334175	859.7956599	82.72350727
818.4293132	73.70987	836.3760205	78.83719653	838.3480288	78.81256849	844.1305718	78.77278938	852.9862313	78.80147114	836.9824913	78.77342781	828.7239975	78.79375608	836.2599628	78.81268241	851.5405816	80.76779925
810.5781505	71.75412612	829.2215509	76.88629605	831.2449488	76.85185636	836.3083342	76.82194695	845.1381584	76.84082406	829.4505618	76.81275332	820.8854672	76.83310817	828.8540917	76.8519972	844.8539916	78.80214798
802.491659	69.79349931	821.3471453	74.92074812	822.6143623	74.89127705	829.2309889	74.86123299	837.2986759	74.88017615	821.5521651	74.85211053	813.4356012	74.87242642	821.052358	74.89134629	836.6791089	76.84152959
794.662874	67.82794675	813.1583487	72.96013085	814.6722073	72.93063768	821.3416665	72.89078298	829.6465304	72.92931856	813.516064	72.89147974	804.7917141	72.91184846	813.9010366	72.9306389	829.2084183	74.88084979
786.8482403	65.87219955	805.2312933	70.99949076	807.4428702	70.96993646	813.1492578	70.93506931	821.8025337	70.95886432	805.4318993	70.93085312	796.8147337	70.9512124	805.3498837	70.97005315	821.8320148	72.92016183
778.7251275	63.91157575	797.226771	69.03885733	798.3331861	69.00939859	805.6104015	68.97439537	814.490814	68.99817033	796.8579162	68.97026902	789.0227561	68.99056027	797.4254776	69.00941287	814.0081156	70.95951271
770.9322455	61.9509232	789.48937	67.07820065	790.1485913	67.04878018	797.6551482	67.0088543	806.439002	67.0375407	789.1609716	67.00960857	781.0192116	67.02992652	788.95174	67.04882024	805.7216586	68.99890378
762.6656714	59.99031089	781.8269874	65.1224407	782.3148436	65.09793799	789.8097817	65.05311026	798.3140267	65.07691739	780.9232916	65.04899509	772.3221898	65.06935295	781.1771813	65.08816686	797.7794033	67.0382649
754.4901588	58.0296892	773.5966944	63.15202014	774.470142	63.13728998	781.2595525	63.10233084	791.2876841	63.11619854	772.6296584	63.08838643	764.3566211	63.10871573	773.4112135	63.12751267	790.5936972	65.07756009
746.4831608	56.06905292	765.4648165	61.19139762	765.7496122	61.16691091	773.7531753	61.13675054	782.3637904	61.15564461	764.9054168	61.12772825	756.3386865	61.14808303	764.7086629	61.16693979	782.5295011	63.1169317
738.7223985	54.10349197	757.4757267	59.23566595	758.3853656	59.20621893	765.4322129	59.17614439	774.1455397	59.19502919	756.8986074	59.16709451	748.6104574	59.18742512	756.4915902	59.20632471	775.030384	61.15625411
729.9404837	52.14292282	749.1768972	57.26525118	749.8005242	57.24563272	757.1341818	57.21553618	766.470863	57.23436656	748.091452	57.20653031	740.0460375	57.22683983	748.5764127	57.24568336	766.0589915	59.19570447
721.7372046	50.17740021	741.0780512	55.30952894	742.4986407	55.28493534	748.8307553	55.25492843	758.002299	55.27377282	739.7238867	55.2459279	730.9351438	55.26630187	740.3435309	55.28506951	758.521119	57.23503021
713.383397	48.21679397	733.1846544	53.35378881	733.6828444	53.32436913	740.2293416	53.29434648	750.5140486	53.31309383	732.1595063	53.28525561	723.2169074	53.30564297	731.6021856	53.32449983	750.1069002	55.27443199
705.1573178	46.26107997	724.8284035	51.38337886	724.7702142	51.3638113	732.2905451	51.33370691	741.252293	51.35256899	723.5358874	51.32467531	715.1393711	51.34501521	724.0353057	51.35402131	740.2921068	53.31395553
696.9020861	44.30046518	716.7987156	49.42765049	717.2244549	49.40313504	723.0372171	49.37318154	733.4678318	49.39191571	714.6017256	49.36412195	706.745743	49.39422154	715.0481303	49.40327957	733.4569765	51.35322003
688.1050221	42.33989733	707.9757427	47.46708768	709.0189015	47.44251595	714.8402164	47.4125643	725.828219	47.43124966	707.1341138	47.40344107	698.1322898	47.42383353	706.5326298	47.44269011	724.7988805	49.39264283
680.0000021	40.37926952	700.1574026	45.50153413	699.9496968	45.47216503	706.1336698	45.4519913	716.6732629	45.47071535	698.0586379	45.44289988	689.8388454	45.4632244	698.1504995	45.48208903	715.91702	47.43208508
671.0034393	38.41381562	691.2384764	43.55078619	692.0144766	43.51152251	697.4927233	43.49141249	708.2406358	43.51992316	689.7354342	43.48229325	680.7479222	43.50268443	689.3932882	43.52152041	706.4836621	45.47157522
662.1172149	36.46306214	682.9783318	41.58527096	683.4497596	41.56074118	689.7320539	41.53075715	700.2795117	41.54947624	680.9245496	41.52172898	671.5006421	41.54215802	680.8131922	41.56093639	697.9323629	43.51098859
653.6159087	34.50246865	673.7164729	39.6296494	674.4134883	39.5903874	679.8955897	39.57028216	690.8670421	39.58896172	672.8351036	39.56110195	663.0622814	39.58156126	672.235947	39.60035206	688.9708419	41.55043765
644.2425072	32.54195072	665.6148781	37.66902362	665.3702076	37.62984087	670.6729809	37.60975376	682.0806248	37.62839295	663.7315833	37.60056248	654.4890801	37.62097617	663.6039993	37.62996579	680.8124996	39.58981677
635.3230537	30.58139346	656.7748521	35.70355861	656.2740192	35.67910557	661.211182	35.64924604	673.2819972	35.66782524	655.3688665	35.639957	644.7849186	35.66048801	653.9232136	35.67928392	671.0455899	37.62933555
626.4853387	28.62082911	648.2303721	33.74297121	647.3273342	33.70874402	651.9673753	33.68871936	664.7702127	33.70723267	646.6203014	33.67938495	636.1959026	33.69990213	645.0789523	33.70891592	662.8319918	35.66871943
616.7712186	26.66034068	639.3131276	31.79222274	637.9562506	31.74822588	642.04046	31.72825193	654.9524695	31.74675324	636.8978141	31.71889727	626.3497029	31.73942517	635.8219584	31.75819706	653.5942932	33.70819216
606.1950309	24.69992694	630.1843838	29.82678264	628.4216323	29.78772191	632.9684597	29.7726135	646.3481341	29.78616869	627.9584449	29.75834174	616.9237318	29.7789118	626.4657955	29.79768012	643.850268	31.74770878
597.652731	22.73933699	621.4584041	27.86621084	619.388292	27.82717451	622.8793306	27.80725667	636.2018886	27.82571772	618.6705151	27.79781641	608.4056569	27.81831977	617.3642003	27.83714099	634.1291687	29.78722344
587.7836332	20.77886198	611.7910225	25.90081737	609.4663602	25.86670408	614.0696767	25.84669183	627.0818757	25.86517783	609.4671899	25.83728375	598.512777	25.85784685	607.2218142	25.86688556	625.1603374	27.8266726
577.886007	18.82819609	602.2276092	23.93541485	599.5933543	23.91603607	603.5492213	23.88627328	617.1399748	23.90470915	599.4398201	23.87682248	588.5431382	23.89738057	597.957383	23.90636043	615.5661301	25.86617415
566.4503552	16.85805014	592.0200621	21.98477811	589.8556888	21.95554968	593.3557646	21.9258264	607.3823615	21.9442245	589.2761643	21.916373	577.6512091	21.93699419	588.0645256	21.95569644	605.9145282	23.90568033
556.2971793	14.89759973	582.8142091	20.02424681	579.5521506	19.9951123	583.9120761	19.96531456	597.0531443	19.98378936	580.5704899	19.95579722	567.6148251	19.97653369	578.1381151	19.99522867	596.3826689	21.94517613
546.0371181	12.93715858	572.9569528	18.05396415	568.7219985	18.0249139	573.6949047	18.00486973	586.8888502	18.02333994	568.7687686	17.99548965	558.3122564	18.02581626	567.137194	18.02504746	586.2010435	19.98472822
535.16814	10.97677018	562.1153443	16.10338007	558.027729	16.07431701	561.8533276	16.04456562	575.35689	16.06300899	558.483836	16.03505068	548.067667	16.05556714	557.6299149	16.06454198	575.6500565	18.02431231
522.9242823	9.016500874	551.7153122	14.14295108	547.3689274	14.10410376	551.684511	14.0841166	565.03118	14.10257355	547.988746	14.0746299	536.934848	14.10500826	546.180178	14.10420393	565.62257	16.06385104
510.8118174	7.066026834	541.2198687	12.18253035	536.2557701	12.15354316	539.9837955	12.12380028	553.4661701	12.14224546	537.1544051	12.11423852	525.7858585	12.13483748	535.6532249	12.15359258	554.1169883	14.10351782
496.8163214	5.096102615	530.185073	10.22215634	525.0362587	10.19318511	528.8463857	10.16343515	541.910452	10.18191656	525.4630079	10.15392138	514.7015669	10.17446774	523.4912818	10.19331622	543.3923667	12.14311694
483.6206349	3.135915756	517.4275563	8.261931569	512.3914898	8.223143887	516.0935132	8.203209979	528.7919741	8.22172304	513.1146409	8.193661146	502.9301962	8.214157523	511.1330673	8.228153541	531.2663757	10.18283746
469.5761809	1.568068416	505.1555412	6.301664736	499.9252683	6.27270049	503.6253209	6.242960135	515.7760126	6.261520634	500.5518004	6.233419491	489.6376681	6.253979083	498.7923877	6.262989335	519.7140841	8.222508275
464.2331053	1.529304681	491.8564675	4.341486875	485.1575456	4.302843164	490.2007354	4.282793141	502.5118667	4.301339723	486.4964611	4.273307125	475.8624395	4.29384245	484.9880129	4.30285525	506.7666837	6.252493296
463.9254899	1.52933133	478.2023399	2.381339769	470.5793838	2.347679385	475.4916381	2.32273742	486.2039526	2.34142249	471.6406944	2.313264096	461.3965244	2.333765645	469.7417174	2.362459379	493.7053953	4.292294828
463.2980036	1.529385686	469.9773113	1.597520319	467.3458154	1.960596831	473.8512083	1.930613535	482.3595784	1.949489529	468.1812734	1.921297787	457.0430161	1.941876792	467.0526499	1.960619689	478.9832729	2.342046885
463.4580018	1.529371825	464.8869998	1.578348003	462.1016899	1.931631172	465.141668	1.901948105	479.1909064	1.920344084	463.6116024	1.892273712	451.3981941	1.922752505	461.6431659	1.941475026	475.5640361	1.9500771
465.3105483	1.529211356	464.606589	1.578372295	460.6577948	1.931756256	466.8719625	1.90179821	479.2687581	1.920337339	461.1144326	1.892490041	452.2076333	1.922682385	460.4087296	1.941581967	470.4242102	1.921102421
468.5715078	1.528928863	463.9130712	1.578432375	460.1957367	1.931796284	466.3409834	1.901844207	478.2708322	1.920423788	461.2629727	1.892477175	452.0187583	1.922698745	460.8675486	1.941542218	469.307566	1.921199157
467.3836038	1.529031771	463.8879833	1.578434551	461.1763126	1.931711337	465.7633875	1.901894245	478.1744079	1.920432141	463.3680041	1.892294815	451.0015407	1.922786868	460.4248759	1.941580568	469.1476345	1.921213014
466.5765319	1.529101688	463.6561152	1.578454632	459.2495296	1.931878257	469.2881301	1.901588954	471.8135299	1.920983194	458.522666	1.89271459	452.2080153	1.922682321	457.0529868	1.941872678	469.2925028	1.921200464
465.0318208	1.529235505	463.6204969	1.578457717	459.8819983	1.931823467	469.6890693	1.901554229	471.3104722	1.921026777	457.6707351	1.892788395	451.3045043	1.922760589	455.5894894	1.941999467	478.4357411	1.920408419
463.4720479	1.529370625	462.4690275	1.578557469	459.9985615	1.931813371	467.9321652	1.901706437	469.6744203	1.921168509	457.2826319	1.892822018	449.0475781	1.922956105	451.654992	1.942340319	478.0893072	1.920438433
463.7002523	1.529350859	462.5414592	1.578551194	460.2915542	1.93178799	466.5998323	1.901821862	470.6661401	1.9210826	460.0774185	1.892579908	448.1884341	1.923030529	453.5511542	1.94217605	477.1669879	1.920518339
462.2136331	1.529479642	464.0931149	1.578416773	459.3642426	1.931868321	468.313376	1.901673421	469.7042434	1.921165927	460.7980911	1.892517477	449.2692604	1.922936896	453.0562436	1.942218925	477.6553533	1.920476036
462.3335405	1.529469257	464.2010479	1.578407422	458.7241667	1.93192377	469.5474826	1.901566515	471.9603631	1.920970483	461.8271553	1.89242833	448.7973933	1.922977771	452.4602109	1.94227056	478.8522885	1.920372349
461.3945027	1.529550607	463.665653	1.578453803	458.8938023	1.931909075	471.4715191	1.901399838	470.144656	1.921127777	462.5471106	1.892365963	448.4080018	1.923011502	452.8667935	1.942235337	479.1828752	1.920343712
460.9073005	1.529592811	464.687298	1.578365296	456.7092496	1.93209832	470.9987304	1.901440799	470.4209821	1.92110384	463.1856649	1.892310645	449.2206027	1.922941104	452.9922422	1.94222447	479.2606575	1.920336978
460.6693252	1.529613428	464.8834465	1.578348302	456.2710634	1.932136279	470.0138727	1.901526126	470.0106019	1.921139393	463.9504444	1.892244394	449.5691885	1.922910903	452.8731331	1.942234787	478.9318009	1.920365471
460.9878968	1.529585833	465.7616514	1.578272221	456.1470081	1.932147027	469.3969295	1.901579575	468.6277162	1.921259192	465.7461835	1.892088831	449.2299996	1.922940284	454.8445985	1.942063996	479.7662037	1.92029319
461.221839	1.529565565	465.5203084	1.57829313	453.1617066	1.932405639	469.1636791	1.901599789	468.2790139	1.921289401	466.0014	1.892066723	451.0868122	1.922779426	454.8789655	1.942061019	477.6691492	1.920474864
461.2696677	1.529561425	466.064657	1.578245972	452.5732677	1.932456615	470.4436859	1.901488905	469.5016683	1.921183484	468.4555179	1.891854124	447.8416145	1.923060556	454.3481962	1.942107	477.5748088	1.92048304
463.6699111	1.529353496	464.3362014	1.578395709	454.4154008	1.932297035	471.1793504	1.901425179	468.6910976	1.921253705	465.8290686	1.892081656	449.0049156	1.922959777	454.5647265	1.942088243	479.4437386	1.920321138
462.4253464	1.529461313	461.8600647	1.578610221	456.1162459	1.932149693	471.5198468	1.901395686	468.6185123	1.921259994	463.9735965	1.892242398	449.4438657	1.922921747	454.3480812	1.942107012	476.9967008	1.920533134
463.5902135	1.529360402	462.4212679	1.578561605	457.1608581	1.9320592	470.5335535	1.901481135	468.6319894	1.921258827	463.3022038	1.892300563	452.4115868	1.922664649	454.856503	1.942062965	476.0865715	1.92061198
462.8717146	1.529422646	463.9786611	1.578426683	458.2151522	1.931967869	469.3399934	1.901584539	469.7069035	1.921165709	461.7723346	1.892433098	453.0197902	1.922611957	455.6116339	1.941997547	476.0062156	1.920618945
463.4990406	1.529368301	463.758834	1.578445727	460.5804756	1.931762966	468.1163108	1.901690554	471.1160263	1.921043639	461.6166011	1.89244659	453.3820014	1.922580578	454.2797767	1.942112928	476.9126952	1.920540419
463.9926089	1.529325546	462.2086018	1.578580025	460.310113	1.931786387	469.7678197	1.901547487	472.4742286	1.920925979	460.9114999	1.892507675	451.6335576	1.922732044	455.4688004	1.942009921	476.3708359	1.920587365
464.1720438	1.529310002	463.1162123	1.578501396	462.4452165	1.931601424	468.7808076	1.901632997	473.618709	1.920826835	461.3065684	1.892473452	451.3158841	1.922759562	455.2127104	1.942032107	476.6802656	1.920560563
464.6283177	1.529270476	462.184206	1.578582138	464.1804841	1.931451104	467.9196608	1.901707604	473.3108867	1.920853501	461.4326906	1.892462527	448.9714645	1.922962656	454.7723056	1.942070259	477.075398	1.920526334
469.2848675	1.528867087	462.0005974	1.578598043	462.2437239	1.931618882	467.6681206	1.9017294	472.7814537	1.920899365	461.114872	1.892490061	450.9243775	1.922793473	454.9981591	1.942050693	476.1078936	1.920610153